<?xml version="1.0" encoding="utf-8"?>
<!-- This URDF was automatically created by SolidWorks to URDF Exporter! Originally created by Stephen Brawner (brawner@gmail.com) 
     Commit Version: 1.6.0-4-g7f85cfe  Build Version: 1.6.7995.38578
     For more information, please see http://wiki.ros.org/sw_urdf_exporter -->
<robot
  name="robot_arm_total">
  <link
    name="base_link">
    <inertial>
      <origin
        xyz="0.63646 0.66199 1.4192"
        rpy="0 0 0" />
      <mass
        value="0.057388" />
      <inertia
        ixx="2.1407E-05"
        ixy="-3.684E-07"
        ixz="1.4486E-06"
        iyy="2.1277E-05"
        iyz="-8.0992E-07"
        izz="1.8195E-05" />
    </inertial>
    <visual>
      <origin
        xyz="0 0 0"
        rpy="0 0 0" />
      <geometry>
        <mesh
          filename="package://robot_arm_total/meshes/base_link.STL" />
      </geometry>
      <material
        name="">
        <color
          rgba="0.79216 0.81961 0.93333 1" />
      </material>
    </visual>
    <collision>
      <origin
        xyz="0 0 0"
        rpy="0 0 0" />
      <geometry>
        <mesh
          filename="package://robot_arm_total/meshes/base_link.STL" />
      </geometry>
    </collision>
  </link>
  <link
    name="Link1">
    <inertial>
      <origin
        xyz="-0.000496131715836512 0.0130844213968387 -0.0293220003193908"
        rpy="0 0 0" />
      <mass
        value="0.0402685764137255" />
      <inertia
        ixx="7.55265668974866E-06"
        ixy="2.78892476554161E-07"
        ixz="1.00226181298171E-10"
        iyy="8.03333187302448E-06"
        iyz="2.12099373648896E-07"
        izz="1.25516858304061E-05" />
    </inertial>
    <visual>
      <origin
        xyz="0 0 0"
        rpy="0 0 0" />
      <geometry>
        <mesh
          filename="package://robot_arm_total/meshes/Link1.STL" />
      </geometry>
      <material
        name="">
        <color
          rgba="0.250980392156863 0.250980392156863 0.250980392156863 1" />
      </material>
    </visual>
    <collision>
      <origin
        xyz="0 0 0"
        rpy="0 0 0" />
      <geometry>
        <mesh
          filename="package://robot_arm_total/meshes/Link1.STL" />
      </geometry>
    </collision>
  </link>
  <joint
    name="Joint0"
    type="revolute">
    <origin
      xyz="0.56587 -1.3811 0.67333"
      rpy="0.13003 -1.2184 -0.59159" />
    <parent
      link="base_link" />
    <child
      link="Link1" />
    <axis
      xyz="0 0 1" />
    <limit
      lower="-1.57"
      upper="1.57"
      effort="10"
      velocity="100" />
  </joint>
  <link
    name="Link2">
    <inertial>
      <origin
        xyz="0.0135 -3.4661E-13 -0.05"
        rpy="0 0 0" />
      <mass
        value="0.015631" />
      <inertia
        ixx="6.6818E-06"
        ixy="-7.3057E-21"
        ixz="4.0658E-20"
        iyy="1.3461E-05"
        iyz="-2.1546E-17"
        izz="8.4448E-06" />
    </inertial>
    <visual>
      <origin
        xyz="0 0 0"
        rpy="0 0 0" />
      <geometry>
        <mesh
          filename="package://robot_arm_total/meshes/Link2.STL" />
      </geometry>
      <material
        name="">
        <color
          rgba="0.79216 0.81961 0.93333 1" />
      </material>
    </visual>
    <collision>
      <origin
        xyz="0 0 0"
        rpy="0 0 0" />
      <geometry>
        <mesh
          filename="package://robot_arm_total/meshes/Link2.STL" />
      </geometry>
    </collision>
  </link>
  <joint
    name="Joint1"
    type="revolute">
    <origin
      xyz="-0.01035 0 -0.028347"
      rpy="-3.1025 0 1.5708" />
    <parent
      link="Link1" />
    <child
      link="Link2" />
    <axis
      xyz="1 0 0" />
    <limit
      lower="-1.57"
      upper="1.57"
      effort="10"
      velocity="100" />
  </joint>
  <link
    name="Link3">
    <inertial>
      <origin
        xyz="0.072988 -0.0069801 0.0010766"
        rpy="0 0 0" />
      <mass
        value="0.091722" />
      <inertia
        ixx="1.5925E-05"
        ixy="4.6258E-10"
        ixz="-1.4948E-14"
        iyy="1.9406E-05"
        iyz="1.3359E-12"
        izz="2.8326E-05" />
    </inertial>
    <visual>
      <origin
        xyz="0 0 0"
        rpy="0 0 0" />
      <geometry>
        <mesh
          filename="package://robot_arm_total/meshes/Link3.STL" />
      </geometry>
      <material
        name="">
        <color
          rgba="0.25098 0.25098 0.25098 1" />
      </material>
    </visual>
    <collision>
      <origin
        xyz="0 0 0"
        rpy="0 0 0" />
      <geometry>
        <mesh
          filename="package://robot_arm_total/meshes/Link3.STL" />
      </geometry>
    </collision>
  </link>
  <joint
    name="Joint2"
    type="continuous">
    <origin
      xyz="0 0 -0.1"
      rpy="0 0.61465 1.5708" />
    <parent
      link="Link2" />
    <child
      link="Link3" />
    <axis
      xyz="0 1 0" />
    <limit
      lower="-1.57"
      upper="1.57"
      effort="10"
      velocity="100" />
  </joint>
  <link
    name="Link4">
    <inertial>
      <origin
        xyz="-0.0034242 -0.00019222 -0.056685"
        rpy="0 0 0" />
      <mass
        value="0.043861" />
      <inertia
        ixx="1.3473E-05"
        ixy="1.4148E-13"
        ixz="-2.7912E-07"
        iyy="2.4173E-05"
        iyz="1.3804E-09"
        izz="1.4237E-05" />
    </inertial>
    <visual>
      <origin
        xyz="0 0 0"
        rpy="0 0 0" />
      <geometry>
        <mesh
          filename="package://robot_arm_total/meshes/Link4.STL" />
      </geometry>
      <material
        name="">
        <color
          rgba="0.79216 0.81961 0.93333 1" />
      </material>
    </visual>
    <collision>
      <origin
        xyz="0 0 0"
        rpy="0 0 0" />
      <geometry>
        <mesh
          filename="package://robot_arm_total/meshes/Link4.STL" />
      </geometry>
    </collision>
  </link>
  <joint
    name="Joint3"
    type="revolute">
    <origin
      xyz="0.1262 0 0"
      rpy="2.4178 0 -1.5708" />
    <parent
      link="Link3" />
    <child
      link="Link4" />
    <axis
      xyz="1 0 0" />
    <limit
      lower="-1.57"
      upper="1.57"
      effort="10"
      velocity="100" />
  </joint>
</robot>